Workbook

Sheet Assessment-level skills
A1: Cat | B1: Skill index | C1: Qbank | D1: Quiz | E1: Tracker | F1: Block introduced | G1: exam (could) | H1: on exam | I1: Skill category | J1: Skill | K1: Assessment-level skill | L1: Requires human grading? | M1: Who | N1: N_NEEDED | O1: N_WRITTEN | P1: comments
A2: 1 | B2: 1 | C2: y | D2: y | E2: y | F2: 1 | G2: 0 | H2: 0 | I2: Programming | J2: P1 | K2: I can identify the cause of common error messages in R. | L2: N | M2: EW | O2: 5
A3: 1 | B3: 2 | C3: y | D3: y | E3: y | F3: 1 | G3: 0 | H3: 0 | I3: Programming | J3: P2 | K3: I can manage libraries/packages in R. | L3: N | M3: EW | O3: 5
A4: 1 | B4: 6 | C4: y | D4: y | E4: y | F4: 1 | G4: 0 | H4: 0 | I4: Programming | J4: P3 | K4: I can modify the arguments of a given R function to arrive at the desired output. | L4: N | M4: JK | O4: 5
A5: 2 | B5: 10 | C5: y | D5: y | E5: y | F5: 1 | G5: 1 | H5: 1 | I5: Summarising | J5: S1 | K5: I can identify whether a variable is continuous, categorical, or ordinal. | L5: N | M5: JK | O5: 5
A6: 2 | B6: 8 | C6: y | D6: y | E6: y | F6: 1 | G6: ? | H6: 1 | I6: Summarising | J6: S2 | K6: I can compute appropriate measure(s) of central tendency for a given variable. | L6: N | M6: EW | O6: 7
A7: 2 | B7: 9 | C7: y | D7: y | E7: y | F7: 1 | G7: ? | H7: 1 | I7: Summarising | J7: S3 | K7: I can compute appropriate measure(s) of dispersion for a given variable. | L7: N | M7: EW | O7: 7
A8: 3 | B8: 33 | C8: y | D8: y | E8: y | F8: 1 | G8: 1 | H8: 0 | I8: Visualising | J8: V1 | K8: I can appropriately plot the distribution of a single variable. | L8: N | M8: JK | O8: 5
A9: 3 | B9: 31 | C9: y | D9: y | E9: y | F9: 1 | G9: 0 | H9: 0 | I9: Visualising | J9: V2 | K9: I can customise the appearance of ggplots. | L9: N | M9: EP | O9: 5
A10: 4 | B10: 14 | C10: y | F10: 2 | G10: 1 | H10: 0 | I10: Analysing | J10: A3 | K10: I can explain what a sampling distribution is. | L10: Y | M10: JK | N10: 1 | O10: 1
A11: 4 | B11: 12 | C11: y | F11: 2 | G11: 1 | H11: 1 | I11: Analysing | J11: A1 | K11: I can calculate the standard error of the mean for a given sample. | L11: N | M11: EW | O11: 5
A12: 4 | B12: 13 | C12: y | F12: 2 | G12: 1 | H12: 1 | I12: Analysing | J12: A2 | K12: I can compute a 95% confidence interval for the population mean. | L12: N | M12: JK | O12: 5
A13: 5 | B13: 24 | C13: y | F13: 2 | G13: 1 | H13: 0 | I13: Inferring | J13: I3 | K13: I can identify how different factors affect the bias and precision of an estimate | L13: N | M13: EP | O13: 5
A14: 5 | B14: 25 | C14: y | F14: 2 | G14: 1 | H14: 0 | I14: Inferring | J14: I4 | K14: I can identify the difference between a Type I error and a Type II error. | L14: N | M14: EW | O14: 6
A15: 5 | B15: 23 | C15: y | F15: 2 | G15: 1 | H15: 0 | I15: Inferring | J15: I2 | K15: I can explain how null hypothesis significance testing (NHST) works. | L15: Y | M15: JK | N15: 1 | O15: 1
A16: 5 | B16: 22 | C16: y | F16: 2 | G16: 1 | H16: 1 | I16: Inferring | J16: I1 | K16: I can appropriately interpret a 95% confidence interval. | L16: N | M16: EP | O16: 5
A17: 1 | B17: 5 | C17: y | F17: 2 | G17: 0 | H17: 0 | I17: Programming | J17: P4 | K17: I can extract specific subsets of a given dataset. | L17: N | M17: JK | O17: 5
A18: 7 | B18: 38 | C18: y | F18: 2 | G18: 0 | H18: 0 | I18: Reflecting | J18: R1 | K18: I can write approximately 200 words reflecting on what I experienced and what I learned in DAPR in Semester 1. | L18: ? | M18: EW/ALL | N18: 1 | O18: 1
A19: 2 | B19: 11 | C19: y | F19: 2 | G19: 1 | H19: 1 | I19: Summarising | J19: S4 | K19: I can transform a variable into z-scores. | L19: N | M19: EP | O19: 5
A20: 4 | B20: 17 | F20: 3 | G20: 0 | H20: 0 | I20: Analysing | J20: A6 | K20: I can implement a given statistical test. | L20: N | M20: JK | O20: 5
A21: 4 | B21: 15 | F21: 3 | G21: 1 | H21: 1 | I21: Analysing | J21: A4 | K21: I can check the assumptions underlying basic statistical tests. | L21: N
A22: 4 | B22: 16 | F22: 3 | G22: 1 | H22: 1 | I22: Analysing | J22: A5 | K22: I can identify the appropriate type of basic statistical test for a given question/design. | L22: N | M22: EW | O22: 6
A23: 6 | B23: 35 | F23: 3 | G23: 1 | H23: 0 | I23: Communicating | J23: C1 | K23: I can describe the steps taken in a given analysis. | L23: Y | N23: ~3
A24: 6 | B24: 36 | F24: 3 | G24: 1 | H24: 1 | I24: Communicating | J24: C2 | K24: I can describe in writing the results of a given basic statistical test. | L24: Y | N24: 3?
A25: 5 | B25: 27 | F25: 3 | G25: 1 | H25: 0 | I25: Inferring | J25: I6 | K25: I can tell the difference between statistical significance and practical significance. | L25: N
A26: 5 | B26: 26 | C26: y | F26: 3 | G26: 1 | H26: 1 | I26: Inferring | J26: I5 | K26: I can identify whether I can or cannot reject the null hypothesis. | L26: N | M26: EW | O26: 6
A27: 5 | B27: 28 | F27: 3 | G27: 1 | H27: 1 | I27: Inferring | J27: I7 | K27: I can define appropriate null and alternative hypotheses for a given research question. | L27: N
B28: 3 | F28: 3 | G28: 0 | H28: 0 | I28: Programming | J28: P5 | K28: I can wrangle/modify data as required for the given analysis task. | L28: N | P28: factor,mutate,pivot
A29: 1 | B29: 4 | F29: 3 | G29: 1 | H29: 0 | I29: Programming | J29: P6 | K29: I can identify what data wrangling/modifications are required for a given analysis task. | L29: N
A30: 2 | B30: 7 | F30: 3 | G30: 0 | H30: 0 | I30: Summarising | J30: S5 | K30: I can compute measures that summarise how two variables are related | L30: N | M30: JK | O30: 5
A31: 3 | B31: 32 | F31: 3 | G31: 1 | H31: 0 | I31: Visualising | J31: V4 | K31: I can appropriately plot how two variables are related | L31: N
A32: 3 | B32: 30 | C32: y | F32: 3 | G32: 1 | H32: 1 | I32: Visualising | J32: V3 | K32: I can appropriately describe patterns of data shown in a plot. | L32: N | M32: EP | O32: 5
A33: 4 | B33: 21 | F33: 4 | G33: 1 | H33: 1 | I33: Analysing | J33: A10 | K33: I can represent binary predictors using treatment coding. | L33: N | M33: EP | O33: 5
A34: 4 | B34: 18 | F34: 4 | G34: 1 | H34: 1 | I34: Analysing | J34: A7 | K34: I can use a fitted simple linear model to predict an outcome value for a given predictor value | L34: N
A35: 4 | B35: 19 | F35: 4 | G35: 1 | H35: 1 | I35: Analysing | J35: A8 | K35: I can appropriately interpret the parameters of a simple linear model. | L35: N | M35: EP | O35: 5
A36: 4 | B36: 20 | F36: 4 | G36: 1 | H36: 1 | I36: Analysing | J36: A9 | K36: I can explain how both a t-test and a correlation can be expressed as a linear model. | L36: Y | N36: 1
A37: 6 | B37: 37 | F37: 4 | G37: 1 | H37: 1 | I37: Communicating | J37: C3 | K37: I can describe in writing the results of a given simple linear model. | L37: Y | N37: 3?
A38: 5 | B38: 29 | F38: 4 | G38: 1 | H38: 1 | I38: Inferring | J38: I8 | K38: I can identify the null hypothesis being tested for the parameters of a linear model. | L38: N | M38: EP | O38: 6
A39: 7 | B39: 39 | C39: y | F39: 4 | G39: 0 | H39: 0 | I39: Reflecting | J39: R2 | K39: I can write approximately 200 words reflecting on what I experienced and what I learned in DAPR in Semester 2. | L39: ? | M39: EW/ALL | N39: 1 | O39: 1
A40: 7 | B40: 40 | F40: 4 | G40: 0 | H40: 0 | I40: Reflecting | J40: R3 | K40: I can rate my confidence across the set of DAPR1 skills. | L40: ? | N40: 1 | O40: 1
...

Sheet OLDQUIZZES
A1: QUIZ | B1: q01 | C1: q02 | D1: q03 | E1: q04 | F1: q05 | G1: q06 | H1: q07 | I1: q08 | J1: q09 | K1: q10
A2: EXAMPLE QUIZ | B2: n | C2: n | D2: V1 | E2: n | F2: n | G2: V2 | H2: n | I2: n | J2: n | K2: n
A3: DAPR1 25-26: Practice Quiz 1
A4: DAPR1 25-26: Practice Quiz 2
A5: DAPR1 25-26: Categorical Data
A6: DAPR1 25-26: Continuous Data
A7: DAPR1 25-26: Describing relationships
A8: DAPR1 25-26: Relationships and functions
A9: DAPR1 25-26: Probability Theory
A10: DAPR1 25-26: Probability Rules
A11: DAPR1 25-26: Random Variables (Discrete)
A12: DAPR1 25-26: Random Variables (Continuous)
A13: DAPR1 25-26: Sampling
A14: DAPR1 25-26: Confidence Intervals
... A18: DAPR1 25-26: Errors, Power, Effect Size, Assumptions
A19: DAPR1 25-26: One sample t-test | B19: A4? | C19: n | D19: A4? | E19: A6 | F19: n | G19: n | H19: A7? | I19: P6? | J19: n | K19: n
A20: DAPR1 25-26: Independent t-test | B20: I5 | C20: n | D20: n | E20: P4? | F20: A4? | G20: A4? | H20: A4? | I20: n | J20: n | K20: n
A21: DAPR1 25-26: All t-tests | B21: A5 | C21: A4? | D21: A7 | E21: n | F21: P3 | G21: P4? | H21: C2 | I21: n | J21: n | K21: n
A22: DAPR1 25-26: Chi-square tests | B22: n | C22: n | D22: A7? | E22: I5 | F22: A4 | G22: A7? | H22: n | I22: n | J22: n | K22: n

Sheet Assessment skills crosstab
A1: Block | B1: Programming | C1: Summarising | D1: Analysing | E1: Inferring | F1: Visualising | G1: Communicating | H1: Reflecting
A2: 1 | B2: =COUNTIFS('Assessment-level skills'!$F$2:$F$986, $A2, 'Assessment-level skills'!$I$2:$I$986, $B$1) -> 3 | C2: =COUNTIFS('Assessment-level skills'!$F$2:$F$986, $A2, 'Assessment-level skills'!$I$2:$I$986, C1) -> 3 | D2: =COUNTIFS('Assessment-level skills'!$F$2:$F$986, $A2, 'Assessment-level skills'!$I$2:$I$986, D1) -> 0 | E2: =COUNTIFS('Assessment-level skills'!$F$2:$F$986, $A2, 'Assessment-level skills'!$I$2:$I$986, E1) -> 0 | F2: =COUNTIFS('Assessment-level skills'!$F$2:$F$986, $A2, 'Assessment-level skills'!$I$2:$I$986, F1) -> 2 | G2: =COUNTIFS('Assessment-level skills'!$F$2:$F$986, $A2, 'Assessment-level skills'!$I$2:$I$986, G1) -> 0 | H2: =COUNTIFS('Assessment-level skills'!$F$2:$F$986, $A2, 'Assessment-level skills'!$I$2:$I$986, H1) -> 0 | I2: =SUM(B2:H2) -> 8
A3: 2 | B3: =COUNTIFS('Assessment-level skills'!$F$2:$F$986, $A3, 'Assessment-level skills'!$I$2:$I$986, $B$1) -> 1 | C3: =COUNTIFS('Assessment-level skills'!$F$2:$F$986, $A3, 'Assessment-level skills'!$I$2:$I$986, C$1) -> 1 | D3: =COUNTIFS('Assessment-level skills'!$F$2:$F$986, $A3, 'Assessment-level skills'!$I$2:$I$986, D$1) -> 3 | E3: =COUNTIFS('Assessment-level skills'!$F$2:$F$986, $A3, 'Assessment-level skills'!$I$2:$I$986, E$1) -> 4 | F3: =COUNTIFS('Assessment-level skills'!$F$2:$F$986, $A3, 'Assessment-level skills'!$I$2:$I$986, F$1) -> 0 | G3: =COUNTIFS('Assessment-level skills'!$F$2:$F$986, $A3, 'Assessment-level skills'!$I$2:$I$986, G$1) -> 0 | H3: =COUNTIFS('Assessment-level skills'!$F$2:$F$986, $A3, 'Assessment-level skills'!$I$2:$I$986, H$1) -> 1 | I3: =SUM(B3:H3) -> 10
A4: 3 | B4: =COUNTIFS('Assessment-level skills'!$F$2:$F$986, $A4, 'Assessment-level skills'!$I$2:$I$986, $B$1) -> 2 | C4: =COUNTIFS('Assessment-level skills'!$F$2:$F$986, $A4, 'Assessment-level skills'!$I$2:$I$986, C$1) -> 1 | D4: =COUNTIFS('Assessment-level skills'!$F$2:$F$986, $A4, 'Assessment-level skills'!$I$2:$I$986, D$1) -> 3 | E4: =COUNTIFS('Assessment-level skills'!$F$2:$F$986, $A4, 'Assessment-level skills'!$I$2:$I$986, E$1) -> 3 | F4: =COUNTIFS('Assessment-level skills'!$F$2:$F$986, $A4, 'Assessment-level skills'!$I$2:$I$986, F$1) -> 2 | G4: =COUNTIFS('Assessment-level skills'!$F$2:$F$986, $A4, 'Assessment-level skills'!$I$2:$I$986, G$1) -> 2 | H4: =COUNTIFS('Assessment-level skills'!$F$2:$F$986, $A4, 'Assessment-level skills'!$I$2:$I$986, H$1) -> 0 | I4: =SUM(B4:H4) -> 13
A5: 4 | B5: =COUNTIFS('Assessment-level skills'!$F$2:$F$986, $A5, 'Assessment-level skills'!$I$2:$I$986, $B$1) -> 0 | C5: =COUNTIFS('Assessment-level skills'!$F$2:$F$986, $A5, 'Assessment-level skills'!$I$2:$I$986, C$1) -> 0 | D5: =COUNTIFS('Assessment-level skills'!$F$2:$F$986, $A5, 'Assessment-level skills'!$I$2:$I$986, D$1) -> 4 | E5: =COUNTIFS('Assessment-level skills'!$F$2:$F$986, $A5, 'Assessment-level skills'!$I$2:$I$986, E$1) -> 1 | F5: =COUNTIFS('Assessment-level skills'!$F$2:$F$986, $A5, 'Assessment-level skills'!$I$2:$I$986, F$1) -> 1 | G5: =COUNTIFS('Assessment-level skills'!$F$2:$F$986, $A5, 'Assessment-level skills'!$I$2:$I$986, G$1) -> 1 | H5: =COUNTIFS('Assessment-level skills'!$F$2:$F$986, $A5, 'Assessment-level skills'!$I$2:$I$986, H$1) -> 2 | I5: =SUM(B5:H5) -> 9
B6: =SUM(B2:B5) -> 6 | C6: =SUM(C2:C5) -> 5 | D6: =SUM(D2:D5) -> 10 | E6: =SUM(E2:E5) -> 8 | F6: =SUM(F2:F5) -> 5 | G6: =SUM(G2:G5) -> 3 | H6: =SUM(H2:H5) -> 3 | I6: =SUM(I2:I5) -> 40

Sheet Lesson-level skills brainstorm
A1: Course-level objectives | B1: Lesson-level objectives | C1: AutoGradable | D1: SkillLevel | E1: OnExam | F1: Block | G1: Comment
A2: Inferring | B2: make an appropriate decision based on a p-value | D2: core | F2: 2 | G2: IMPORTANT: green font means "Elizabeth has already added this to her Big List of Skills", please write new skill ideas in non-green
A3: Inferring | B3: identify a measure of uncertainty in an estimate | F3: 2
A4: Inferring | B4: calculate/estimate a standard error for a single mean | F4: 2
A5: Inferring | B5: construct a confidence interval for a single mean | F5: 3
A6: Inferring | B6: draw a conclusion about a test of a single mean | F6: 3
A7: Analysing | B7: Identify when linear model coefficients are statistically significant. | C7: Y | F7: 4 | G7: JK: curious about whether the "meaning" of model parameters depends on significance? if the above skills changed to "interpret the slope..." then perhaps we don't need these two? EP: In my view, the "meaning" of a parameter doesn't change depending on significance, since for me, the "meaning" is its numeric value (estimation)—and then the significance is an additional layer of interpretation (hypothesis testing). (also paves the way in case any of them learn Bayes down the road)
A8: Analysing | B8: Identify the null hypothesis being tested for linear model coefficients. | C8: Y | F8: 4
A9: Analysing | B9: Explain the equivalence between a t-test and a linear model. | C9: N | D9: merit | F9: 4
A10: Analysing | B10: Explain the equivalence between correlation and a linear model. | C10: N | D10: merit | F10: 4
A11: Inferring | B11: Explain the meaning of the intercept of a linear model with one continuous predictor. | C11: N | F11: 4
A12: Inferring | B12: Explain the meaning of the slope of a linear model with one continuous predictor. | C12: N | F12: 4
A13: Inferring | B13: Explain the meaning of the intercept of a linear model with one binary predictor. | C13: N | F13: 4
A14: Inferring | B14: Explain the meaning of the slope of a linear model with one binary predictor. | C14: N | F14: 4
A15: Reflecting | B15: Reflect on individual learning experience across the course | C15: N | D15: core | F15: ? | G15: i guess we need this if we want students to do it?
A16: Coding | B16: Read dataset into R | C16: Y | D16: core | E16: N | F16: 1+
A17: Coding | B17: Create a new variable in a dataframe | C17: Y | D17: core | E17: N | F17: 1+
A18: Coding | B18: Subset a dataframe | C18: Y | D18: core | E18: N | F18: 1+
A19: Coding | B19: Filter a dataframe | C19: Y | D19: core | E19: N | F19: 1+
A20: Coding | B20: Handle missing values when calculating descriptive statistics | C20: Y | D20: core | E20: N | F20: 1+
A21: Coding | B21: Load a library in R | C21: Y | D21: core | F21: 1+
A22: Communicating | B22: As if for a paper/dissertation, describe the data/variables used in a statistical analysis. | C22: N | D22: core | F22: 1+
A23: Plotting | B23: Visualise a categorical variable on its own | C23: N | D23: core | E23: N | F23: 1+
A24: Plotting | B24: Visualise a continuous variable on its own | C24: N | D24: core | E24: N | F24: 1+
A25: Plotting | B25: Visualise the association between two continuous variables | C25: N | D25: core | E25: N | F25: 1+ | G25: UN - Currently correlation is taught in block 4, so where this is taught might be important for the block column here
A26: Plotting | B26: Visualise the association between one continuous and one categorical variable | C26: N | D26: core | E26: N | F26: 1+
A27: Plotting | B27: Combine plots using patchwork | C27: Y | D27: core | F27: 1+ | G27: UN - Probably advanced as a skill, rather than a core one?
A28: Summarising | B28: Numerically summarise a categorical variable | C28: Y | D28: core | F28: 1+
A29: Summarising | B29: Numerically summarise a continuous variable | C29: Y | D29: core | F29: 1+
A30: Summarising | B30: Identify measure(s) of central tendency for a continuous variable [mean, median] | C30: Y | D30: core | F30: 1+
A31: Summarising | B31: Identify measure(s) of dispersion for a continuous variable [sd, variance, IQR] | C31: Y | D31: core | F31: 1+ | G31: UN - variance should probably not appear there as in unit of measurement ^2
A32: Summarising | B32: Identify measure(s) of central tendency for a categorical variable [mode] | C32: Y | D32: core | F32: 1+ | G32: UN - nominal variable, rather than categorical
A33: Summarising | B33: Identify measure(s) of central tendency for an ordinal variable [mode] | C33: Y | D33: core | F33: 1+ | G33: UN - both mode and median are acceptable
A34: Summarising | B34: Identify measure(s) of dispersion for an ordinal variable [IQR] | C34: Y | D34: core | F34: 1+
A35: Summarising | B35: Identify a situation in which a variable's mean and median would differ [skewed distribution] | C35: Y | D35: merit | F35: 1+
A36: Summarising | B36: Numerically summarise the association between two continuous variables | C36: Y | D36: core | F36: 1+ | G36: UN - currently taught in block 4, where this is taught might inform the block column
A37: Summarising | B37: Numerically summarise the association between two categorical variables | C37: Y | D37: core | F37: 1+
A38: Summarising | B38: Numerically summarise the association between one continuous and one categorical variable | C38: Y | D38: core | F38: 1+
A39: Summarising | B39: Explain the relationship between covariance and correlation. | C39: N | D39: merit | F39: 1+
A40: Summarising | B40: Identify measure(s) of association between two continuous variables [cov, cor, r^2] | C40: Y | F40: 1+
...
